# 14. 예외 처리

## try, catch, throw

C++의 예외 처리 메커니즘은 **프로그램 실행 중 발생할 수 있는 비정상적인 상황(예외)**을
 안전하게 감지하고 처리하기 위한 구조이다. 이를 위해 **`try`, `catch`, `throw` 키워드**를 사용한다.

### ✅ 1. 기본 구조

```
try {
    // 예외가 발생할 수 있는 코드
}
catch (예외_타입 변수) {
    // 예외 처리 코드
}
```

#### 📌 예시

```
try {
    int a = 5, b = 0;
    if (b == 0)
        throw std::runtime_error("Division by zero");
    int result = a / b;
}
catch (const std::runtime_error& e) {
    std::cerr << "오류 발생: " << e.what() << "\n";
}
```

> `throw`는 예외를 **발생시키는 키워드**,
>  `catch`는 예외를 **포착하고 처리**하는 코드 블록
>  `try`는 예외 발생 가능성이 있는 코드를 **감싸는 보호 블록**

### ✅ 2. `throw` — 예외 발생

```
throw 값;  // 어떤 타입도 가능 (객체, 기본형, 사용자 정의 타입)
```

#### 📌 예시

```
throw 42;                          // int 예외
throw std::string("에러 발생");    // std::string 예외
throw MyException("File not found");  // 사용자 정의 예외
```

### ✅ 3. `catch` — 예외 포착

```
catch (int e) { ... }
catch (std::string e) { ... }
catch (const std::exception& e) { ... }
```

#### 📌 순서 주의

- 여러 개의 `catch` 블록 사용 가능
- **위에서 아래로 차례대로 검사**
- **구체적인 타입 먼저, 범용 타입 나중에**

```
catch (const std::out_of_range& e) { ... }    // 먼저
catch (const std::exception& e) { ... }       // 나중
```

### ✅ 4. catch-all (`...`) — 모든 예외 처리

```
catch (...) {
    std::cerr << "알 수 없는 예외 발생!\n";
}
```

- 어떤 타입의 예외든지 잡음
- 마지막 수단으로만 사용하는 것이 좋음

### ✅ 5. 사용자 정의 예외 클래스

모든 예외는 `std::exception` 또는 그 파생 클래스를 상속받아 정의할 수 있음.

```
class MyError : public std::exception {
public:
    const char* what() const noexcept override {
        return "사용자 정의 예외 발생!";
    }
};
```

사용:

```
throw MyError();
```

### ✅ 6. 예외 전파 (Exception Propagation)

함수 안에서 `throw`를 호출하고, 그 예외를 **호출한 상위 함수에서 `catch`** 할 수 있음

```
void risky() {
    throw std::runtime_error("에러 발생");
}

int main() {
    try {
        risky();
    } catch (const std::exception& e) {
        std::cout << e.what();
    }
}
```

### 📎 예외와 noexcept

```
void safeFunc() noexcept {
    // 예외를 절대 던지지 않음
}
```

- `noexcept` 함수에서 예외 발생 시 `std::terminate()` 호출됨
- C++11부터 제공

### 📎 예외와 성능

- 예외는 **오류 처리 로직에 적합**하지만 **일반 제어 흐름에는 부적절**
- 런타임 비용이 있으며, 남용할 경우 성능 저하와 복잡도 증가 가능

### ✅ 요약 정리

| 키워드     | 의미                                   |
| ---------- | -------------------------------------- |
| `try`      | 예외가 발생할 수 있는 코드 감싸기      |
| `throw`    | 예외를 발생시킴                        |
| `catch`    | 특정 타입의 예외를 처리                |
| `...`      | 모든 예외를 포괄적으로 처리            |
| `noexcept` | 예외가 발생하지 않음을 컴파일러에 알림 |

### ✅ 결론

> `try-catch-throw`는 C++에서 **강력하고 안전한 예외 처리 프레임워크**이며,
>  프로그램을 **강제 종료시키지 않고 오류 상황을 제어 흐름으로 처리**할 수 있도록 해준다.
>
> **사용자 정의 예외 클래스**, **catch 순서**, **예외 전파**, **noexcept 함수 처리**까지
>  상황에 맞게 적절히 활용하면 **안정적이고 유지보수 가능한 코드**를 작성할 수 있다.

## 예외 클래스 정의

C++에서는 표준 라이브러리의 예외 클래스(`std::exception` 및 그 파생 클래스들)를 사용할 수 있지만,
 **도메인에 특화된 오류 정보를 표현하고 싶을 때**는 **사용자 정의 예외 클래스**를 만드는 것이 유용하다.

### ✅ 1. 표준 예외 클래스 계층 구조

```
std::exception
├── std::logic_error
│   ├── std::invalid_argument
│   ├── std::domain_error
│   ├── std::length_error
│   └── std::out_of_range
└── std::runtime_error
    ├── std::range_error
    ├── std::overflow_error
    └── std::underflow_error
```

> 사용자 정의 예외는 보통 `std::exception` 또는 그 하위 클래스 중 하나를 상속해서 정의한다.

### ✅ 2. 가장 기본적인 사용자 정의 예외 클래스

```
class MyException : public std::exception {
public:
    const char* what() const noexcept override {
        return "MyException: Something went wrong";
    }
};
```

```
try {
    throw MyException();
} catch (const std::exception& e) {
    std::cerr << e.what() << "\n";  // 출력: MyException: Something went wrong
}
```

- `what()`은 예외 메시지를 반환하는 함수
- 반드시 `noexcept`로 선언 (C++ 표준 요구사항)

### ✅ 3. 예외 메시지 커스터마이징

```
class FileNotFound : public std::runtime_error {
public:
    explicit FileNotFound(const std::string& filename)
        : std::runtime_error("File not found: " + filename) {}
};
```

```
throw FileNotFound("config.json");
```

- `std::runtime_error`을 상속하면 생성자에서 **에러 메시지 초기화**가 간편함
- `std::logic_error`는 프로그래밍 실수 (논리 오류)에 적합

### ✅ 4. 예외 클래스에 추가 정보 저장

```
class ValidationError : public std::exception {
    std::string field;
    std::string msg;

public:
    ValidationError(const std::string& f, const std::string& m)
        : field(f), msg("Validation failed for " + f + ": " + m) {}

    const char* what() const noexcept override {
        return msg.c_str();
    }

    const std::string& getField() const noexcept {
        return field;
    }
};
```

```
try {
    throw ValidationError("email", "must contain @");
} catch (const ValidationError& e) {
    std::cout << e.getField() << " => " << e.what() << "\n";
}
```

- `what()`은 에러 설명 문자열
- `getField()`는 부가 정보를 제공

### ✅ 예외 클래스 정의 시 체크포인트

| 항목                  | 권장 여부 | 설명                                              |
| --------------------- | --------- | ------------------------------------------------- |
| `std::exception` 상속 | ✅         | 표준 예외와의 호환성을 위해                       |
| `what()` 재정의       | ✅         | 예외 메시지를 문자열로 반환                       |
| `noexcept` 선언       | ✅         | `what()` 함수는 반드시 예외를 던지지 않아야 함    |
| 생성자에 메시지 전달  | ✅         | 유연한 오류 메시지 제공                           |
| 추가 필드             | 선택적    | 발생 위치, 코드, 오류 종류 등 부가 정보 포함 가능 |

### ✅ 결론

> 사용자 정의 예외 클래스는 **도메인 오류를 명확하게 표현**하고,
>  **에러 처리 로직을 구조화하는 데 필수적인 도구**다.
>
> 표준 예외 계층을 활용하여 정의하면 **호환성과 가독성**이 높아지고,
>  `what()`을 통해 **의미 있는 에러 메시지를 제공하는 것**이 예외 설계의 핵심이다.

## 표준 예외 계층 구조

### 🧱 1. 기본 구조 개요

```
                std::exception
                      │
          ┌───────────┼────────────────────┐
          │           │                    │
   std::logic_error  std::runtime_error  기타 파생 예외
          │           │
  ┌───────┴──────┐ ┌──┴───────────┐
  │              │ │              │
domain_error  invalid_argument   range_error  overflow_error
```

모든 예외는 최상위 클래스인 `std::exception`에서 파생되며, **주로 논리적 오류**와 **실행 중 오류**를 구분하는 두 가지 주요 하위 클래스로 나뉘어.

### 📌 2. `std::exception` – 최상위 예외 클래스

- 정의: `#include <exception>`

- 설명: 모든 표준 예외의 부모. 순수 가상 함수 `what()`을 포함하고 있음.

- 메서드:

  ```
  virtual const char* what() const noexcept;
  ```

### 📚 3. 파생 예외 클래스 계층 상세

#### ✅ `std::logic_error`

> 프로그래머의 실수로 발생하는 논리적 오류
>  컴파일 후에도 잡히지 않는 **논리적 버그**

- 예: 잘못된 인자 전달, 사전 조건 위반

**하위 클래스:**

| 클래스명                | 설명                                     |
| ----------------------- | ---------------------------------------- |
| `std::invalid_argument` | 잘못된 인자가 전달됨                     |
| `std::domain_error`     | 수학적 정의 영역 벗어남 (예: `sqrt(-1)`) |
| `std::length_error`     | 벡터 등의 최대 길이 초과 시              |
| `std::out_of_range`     | 유효하지 않은 인덱스 접근                |

```
throw std::invalid_argument("잘못된 입력");
```

#### ✅ `std::runtime_error`

> 실행 중 시스템 상태, 외부 환경 등으로 인해 발생하는 오류

**하위 클래스:**

| 클래스명               | 설명                         |
| ---------------------- | ---------------------------- |
| `std::range_error`     | 표현 범위를 벗어나는 결과    |
| `std::overflow_error`  | 수치 연산 중 오버플로우 발생 |
| `std::underflow_error` | 수치 연산 중 언더플로우 발생 |

```
throw std::overflow_error("오버플로우 발생!");
```

#### ✅ 기타 파생 클래스

| 클래스명                 | 설명                                          |
| ------------------------ | --------------------------------------------- |
| `std::bad_alloc`         | `new` 연산 실패 (메모리 부족)                 |
| `std::bad_cast`          | `dynamic_cast` 실패 시                        |
| `std::bad_typeid`        | 타입 정보 요청 실패                           |
| `std::ios_base::failure` | 스트림 입출력 실패 (`fstream`, `ifstream` 등) |

```
throw std::bad_alloc(); // 메모리 부족 예외
```

### 🛠️ 4. 예외 계층 구조 다이어그램 (ASCII)

```
std::exception
├── std::logic_error
│   ├── std::invalid_argument
│   ├── std::domain_error
│   ├── std::length_error
│   └── std::out_of_range
├── std::runtime_error
│   ├── std::range_error
│   ├── std::overflow_error
│   └── std::underflow_error
├── std::bad_alloc
├── std::bad_cast
├── std::bad_typeid
└── std::ios_base::failure
```

### 🧪 5. 예시 코드

```
#include <iostream>
#include <stdexcept>

void divide(int a, int b) {
    if (b == 0) throw std::domain_error("0으로 나눌 수 없습니다");
    std::cout << a / b << std::endl;
}

int main() {
    try {
        divide(10, 0);
    } catch (const std::exception& e) {
        std::cerr << "예외 발생: " << e.what() << std::endl;
    }
}
```

출력:

```
예외 발생: 0으로 나눌 수 없습니다
```

### ✅ 6. 실전 사용 시 팁

| 상황               | 사용할 예외 클래스                            |
| ------------------ | --------------------------------------------- |
| 잘못된 인자        | `std::invalid_argument`                       |
| 자료구조 범위 초과 | `std::out_of_range`                           |
| 메모리 부족        | `std::bad_alloc`                              |
| 입출력 오류        | `std::ios_base::failure`                      |
| 연산 오류          | `std::overflow_error`, `std::underflow_error` |

## noexcept 지정자

### 🔹 1. 기본 문법

```
void func() noexcept;
```

이렇게 선언된 함수는 **예외를 던지지 않겠다고 명시**하는 것이며, 만약 예외를 던지면 `std::terminate()`가 호출돼 프로그램이 강제 종료돼.

### 🔸 2. noexcept 사용 이유

| 이유                    | 설명                                                         |
| ----------------------- | ------------------------------------------------------------ |
| ✅ 최적화 가능           | 컴파일러가 예외 처리를 위한 구조 (예: 스택 언와인딩 등)를 생략 |
| ✅ 이동 연산자 조건 판단 | `std::move_if_noexcept`와 함께 사용되어 복사보다 move 선호 여부 판단 |
| ✅ 코드 안정성           | 함수의 예외 안전성을 문서화하고 강제                         |
| ✅ 템플릿 평가           | 조건부 `noexcept` 표현식 사용 가능 (`noexcept(expr)`)        |

### 🔹 3. 기본 예제

```
void safeFunc() noexcept {
    // 예외를 던지지 않음
}

void riskyFunc() {
    throw std::runtime_error("예외!");
}
```

`safeFunc()`은 `noexcept` 함수이므로 절대 예외를 던지면 안 됨.

### 🔸 4. 예외를 던지면 어떤 일이 벌어질까?

```
void badFunc() noexcept {
    throw std::runtime_error("Boom!");
}

int main() {
    badFunc(); // std::terminate() 호출됨
}
```

> 출력 없이 강제 종료 (예외는 포착되지 않음)

### 🔹 5. `noexcept(expr)` 조건부 사용

```
template<typename T>
void wrapper(T&& t) noexcept(noexcept(t.run())) {
    t.run();
}
```

- `t.run()`이 noexcept이면 이 함수도 noexcept
- 아니면 이 함수도 예외를 던질 수 있다고 판단됨

➡ 템플릿, 람다, STL 내부에서 매우 자주 사용됨

### 🔸 6. `noexcept`와 이동 연산자 (move constructor / move assignment)

```
class MyClass {
public:
    MyClass(MyClass&&) noexcept;           // 이동 생성자
    MyClass& operator=(MyClass&&) noexcept; // 이동 대입 연산자
};
```

- 표준 컨테이너 (`std::vector`, `std::map`)는 **이동이 `noexcept`일 때만 move 사용**
- 아니면 복사 fallback

```
std::vector<MyClass> v;
v.push_back(std::move(obj)); // 이동 연산자에 noexcept 없으면 복사됨
```

### 📌 7. `noexcept` vs `throw()`

| 항목        | `throw()` (C++98/03) | `noexcept` (C++11~)     |
| ----------- | -------------------- | ----------------------- |
| 의미        | 예외를 던지지 않음   | 예외를 던지지 않음      |
| 상태        | 폐기됨 (deprecated)  | 표준                    |
| 작성법      | `void f() throw();`  | `void f() noexcept;`    |
| 조건부 작성 | 불가                 | 가능 (`noexcept(expr)`) |
| 검사 방식   | 런타임 검사          | 컴파일 타임 검사        |

### 🔹 8. 예외 안전성과의 연계

- `noexcept`는 예외 안전성 보장을 문서화함
- noexcept 함수는 **"예외를 절대 던지지 않음"이라는 계약(contract)**을 의미함
- 이를 통해 호출자는 **예외 처리를 생략**하거나 **`std::terminate()`를 기대**할 수 있음

### ✅ 9. 요약 정리표

| 항목             | 설명                                                      |
| ---------------- | --------------------------------------------------------- |
| `noexcept`       | 함수가 예외를 던지지 않음을 명시                          |
| `noexcept(expr)` | 조건부 noexcept (템플릿, SFINAE에 필수)                   |
| 예외 던지면      | `std::terminate()` 강제 종료                              |
| STL 영향         | `std::vector`, `std::move_if_noexcept` 등에서 중요한 역할 |
| 최적화 영향      | 예외 처리 스택 생략으로 성능 향상 가능                    |

### 🧪 마무리 예제

```
#include <iostream>
#include <stdexcept>

void f() noexcept {
    std::cout << "정상 실행\n";
}

void g() noexcept {
    throw std::runtime_error("예외 발생"); // std::terminate() 호출됨
}

int main() {
    f();

    try {
        g(); // 여기 도달하지 못함
    } catch (...) {
        std::cout << "catch 블록\n";
    }

    return 0;
}
```

> 출력 결과:

```
정상 실행
(그 뒤는 terminate로 종료)
```

## 예외 안전성 수준

C++ 표준 라이브러리 및 일반적인 코드 설계에서는 예외 발생 시 프로그램의 일관성과 안전성을 유지하기 위한 **예외 안전성(exception safety)** 개념이 중요하게 다루어진다. 예외 안전성 수준은 예외가 발생했을 때 함수 또는 객체가 **어떤 상태를 보장하는가**를 기술하는 표준적인 체계이며, 대표적으로 다음 세 가지 수준이 정의된다.

### 1. 기본 보장 (Basic Guarantee)

**정의**: 예외가 발생한 경우에도, 해당 객체 또는 프로그램은 **일관된(valid) 상태를 유지**하며, **자원 누수(leak)는 발생하지 않는다.**

이 보장은 C++ 표준 라이브러리의 대부분의 연산에서 최소한으로 제공되는 수준이다. 예외가 발생하더라도 프로그램의 상태가 파괴되지 않고, 객체는 여전히 정의된 연산을 수행할 수 있어야 한다.

**특징**:

- 불변식(invariant)은 유지된다.
- 누수 없는 자원 해제가 보장된다.
- 객체의 내부 상태는 변경되었을 수 있다.

**예시**:

```
std::vector<int> v;
try {
    v.push_back(get_value_that_may_throw());
} catch (...) {
    // v는 여전히 유효한 상태다.
}
```

### 2. 강력 보장 (Strong Guarantee)

**정의**: 예외가 발생한 경우, 연산의 수행 이전 상태로 **완전히 복구(rollback)** 된다. 즉, 연산이 **원자성(atomicity)**을 가진 것처럼 동작한다.

이 보장은 프로그램의 상태가 예외 발생 이전과 동일하게 유지된다는 점에서 높은 수준의 안정성을 제공한다. 함수 호출이 성공적으로 완료되거나, 아무런 변경도 발생하지 않은 것처럼 보장된다.

**특징**:

- 상태 롤백이 보장된다.
- 예외 발생 이전의 상태로 복구된다.
- 임시 객체와 복사/이동 생성자를 통한 설계가 필요하다.

**예시**:

```
std::string s = "Hello";
try {
    s.replace(0, 3, function_that_may_throw());
    // 예외가 발생하지 않으면 s는 새 문자열로 변경됨
} catch (...) {
    // 예외가 발생해도 s는 여전히 "Hello"
}
```

### 3. 예외 없음 보장 (No-Throw Guarantee)

**정의**: 해당 연산 또는 함수는 **절대 예외를 발생시키지 않는다.**

이 보장은 가장 높은 수준의 예외 안전성을 의미하며, 일반적으로 `noexcept` 지정자를 통해 표현된다. C++ 표준 라이브러리는 `swap`, 소멸자(destructor), 이동 생성자(move constructor) 등의 연산에 대해 이 수준의 보장을 요구하거나 권장한다.

**특징**:

- 예외 발생 가능성이 존재하지 않음
- `noexcept` 키워드로 명시적으로 선언 가능
- 성능 최적화에 기여함 (예: `std::move_if_noexcept`)

**예시**:

```
void safe_function() noexcept {
    // 예외를 절대 발생시키지 않음
}
```

### 예외 안전성과 STL의 관계

표준 템플릿 라이브러리(STL)는 대부분의 연산에서 최소한 기본 보장을 제공한다. 일부 연산은 강력 보장을 제공하며, 예외 없음 보장은 이동 연산자나 소멸자 등 특정한 상황에서 요구된다.

| 연산                       | 보장 수준      |
| -------------------------- | -------------- |
| `std::vector::push_back()` | 기본 보장      |
| `std::string::replace()`   | 강력 보장      |
| `std::swap()`              | 예외 없음 보장 |

### 예외 안전성과 `noexcept`의 관계

| 구분      | `noexcept`                                | 예외 안전성 수준                |
| --------- | ----------------------------------------- | ------------------------------- |
| 의미      | 예외를 절대 던지지 않음을 문법적으로 명시 | 예외 발생 시 상태의 안전성 보장 |
| 표현 방식 | `void f() noexcept`                       | 문서화 또는 설계 의도로 표현    |
| 사용 목적 | 컴파일러 최적화, API 안정성               | 상태 복구 및 자원 정리의 보장   |

`noexcept`가 적용된 함수는 반드시 예외 없음 보장을 충족해야 하며, 그렇지 않은 경우 `std::terminate()`가 호출된다. 반대로, 기본 보장이나 강력 보장은 `noexcept`가 없어도 충분히 의미를 가질 수 있다.

### 요약 정리

| 보장 수준      | 설명                                              | 일반 적용 예        |
| -------------- | ------------------------------------------------- | ------------------- |
| 기본 보장      | 예외 발생 시에도 객체는 유효하며 자원 누수 없음   | 대부분의 STL 연산   |
| 강력 보장      | 예외 발생 시 이전 상태로 복구됨                   | 일부 복사/이동 연산 |
| 예외 없음 보장 | 절대 예외가 발생하지 않음, `noexcept`로 명시 가능 | 소멸자, `swap()` 등 |

